{"timestamp": "2025-05-31T21:36:20.750995", "type": "WARNING", "message": "Small chunk detected in KTI Dispatch Guide.pdf, chunk 4: 17 chars"}
{"timestamp": "2025-05-31T21:36:20.751760", "type": "WARNING", "message": "Small chunk detected in KTI Dispatch Guide.pdf, chunk 214: 17 chars"}
{"timestamp": "2025-05-31T21:36:20.752012", "type": "WARNING", "message": "Small chunk detected in KTI Dispatch Guide.pdf, chunk 220: 17 chars"}
{"timestamp": "2025-05-31T21:36:25.093074", "type": "WARNING", "message": "Small chunk detected in KTI Dispatch Guide.pdf, chunk 4: 17 chars"}
{"timestamp": "2025-05-31T21:36:25.093476", "type": "WARNING", "message": "Small chunk detected in KTI Dispatch Guide.pdf, chunk 214: 17 chars"}
{"timestamp": "2025-05-31T21:36:25.093725", "type": "WARNING", "message": "Small chunk detected in KTI Dispatch Guide.pdf, chunk 220: 17 chars"}
{"timestamp": "2025-05-31T21:36:28.123824", "type": "WARNING", "message": "Small chunk detected in KTI Dispatch Guide.pdf, chunk 4: 17 chars"}
{"timestamp": "2025-05-31T21:36:28.124245", "type": "WARNING", "message": "Small chunk detected in KTI Dispatch Guide.pdf, chunk 214: 17 chars"}
{"timestamp": "2025-05-31T21:36:28.124489", "type": "WARNING", "message": "Small chunk detected in KTI Dispatch Guide.pdf, chunk 220: 17 chars"}
{"timestamp": "2025-05-31T21:36:31.397710", "type": "WARNING", "message": "Small chunk detected in KTI Dispatch Guide.pdf, chunk 4: 17 chars"}
{"timestamp": "2025-05-31T21:36:31.398126", "type": "WARNING", "message": "Small chunk detected in KTI Dispatch Guide.pdf, chunk 214: 17 chars"}
{"timestamp": "2025-05-31T21:36:31.398373", "type": "WARNING", "message": "Small chunk detected in KTI Dispatch Guide.pdf, chunk 220: 17 chars"}
{"timestamp": "2025-05-31T22:09:31.820779", "type": "ERROR", "message": "Error during index save operation: Failed to save texts file: [Errno 2] No such file or directory: '/workspace/llm/WorkApp2/data/index/texts.npy.tmp' -> '/workspace/llm/WorkApp2/data/index/texts.npy'", "traceback": "Traceback (most recent call last):\n  File \"/workspace/llm/WorkApp2/core/vector_index/storage_manager.py\", line 237, in _save_texts_file\n    os.replace(temp_path, final_path)\nFileNotFoundError: [Errno 2] No such file or directory: '/workspace/llm/WorkApp2/data/index/texts.npy.tmp' -> '/workspace/llm/WorkApp2/data/index/texts.npy'\n\nThe above exception was the direct cause of the following exception:\n\nTraceback (most recent call last):\n  File \"/workspace/llm/WorkApp2/core/vector_index/storage_manager.py\", line 90, in save_index\n    self._save_texts_file(texts, paths[\"temp_texts\"], paths[\"texts\"])\n  File \"/workspace/llm/WorkApp2/core/vector_index/storage_manager.py\", line 240, in _save_texts_file\n    raise IOError(f\"Failed to save texts file: {str(e)}\") from e\nOSError: Failed to save texts file: [Errno 2] No such file or directory: '/workspace/llm/WorkApp2/data/index/texts.npy.tmp' -> '/workspace/llm/WorkApp2/data/index/texts.npy'\n"}
{"timestamp": "2025-05-31T22:15:12.343781", "type": "ERROR", "message": "Error during index save operation: Failed to save texts file: [Errno 2] No such file or directory: '/workspace/llm/WorkApp2/data/index/texts.npy.tmp' -> '/workspace/llm/WorkApp2/data/index/texts.npy'", "traceback": "Traceback (most recent call last):\n  File \"/workspace/llm/WorkApp2/core/vector_index/storage_manager.py\", line 237, in _save_texts_file\n    os.replace(temp_path, final_path)\nFileNotFoundError: [Errno 2] No such file or directory: '/workspace/llm/WorkApp2/data/index/texts.npy.tmp' -> '/workspace/llm/WorkApp2/data/index/texts.npy'\n\nThe above exception was the direct cause of the following exception:\n\nTraceback (most recent call last):\n  File \"/workspace/llm/WorkApp2/core/vector_index/storage_manager.py\", line 90, in save_index\n    self._save_texts_file(texts, paths[\"temp_texts\"], paths[\"texts\"])\n  File \"/workspace/llm/WorkApp2/core/vector_index/storage_manager.py\", line 240, in _save_texts_file\n    raise IOError(f\"Failed to save texts file: {str(e)}\") from e\nOSError: Failed to save texts file: [Errno 2] No such file or directory: '/workspace/llm/WorkApp2/data/index/texts.npy.tmp' -> '/workspace/llm/WorkApp2/data/index/texts.npy'\n"}
{"timestamp": "2025-05-31T22:25:41.460506", "type": "ERROR", "message": "Error during index save operation: Failed to save texts file: Temp file was not created: /workspace/llm/WorkApp2/data/index/texts.npy.tmp", "traceback": "Traceback (most recent call last):\n  File \"/workspace/llm/WorkApp2/core/vector_index/storage_manager.py\", line 255, in _save_texts_file\n    raise IOError(f\"Temp file was not created: {temp_path}\")\nOSError: Temp file was not created: /workspace/llm/WorkApp2/data/index/texts.npy.tmp\n\nThe above exception was the direct cause of the following exception:\n\nTraceback (most recent call last):\n  File \"/workspace/llm/WorkApp2/core/vector_index/storage_manager.py\", line 90, in save_index\n    self._save_texts_file(texts, paths[\"temp_texts\"], paths[\"texts\"])\n  File \"/workspace/llm/WorkApp2/core/vector_index/storage_manager.py\", line 268, in _save_texts_file\n    raise IOError(f\"Failed to save texts file: {str(e)}\") from e\nOSError: Failed to save texts file: Temp file was not created: /workspace/llm/WorkApp2/data/index/texts.npy.tmp\n"}
{"timestamp": "2025-05-31T23:22:26.460349", "type": "ERROR", "message": "Empty or invalid file: test_text_procedures.txt"}
{"timestamp": "2025-05-31T23:22:26.461461", "type": "ERROR", "message": "Error processing file test_text_procedures.txt: Empty or invalid file: test_text_procedures.txt", "traceback": "Traceback (most recent call last):\n  File \"/workspace/llm/WorkApp2/core/document_ingestion/enhanced_file_processor.py\", line 314, in process_file_upload\n    raise ValueError(error_msg)\nValueError: Empty or invalid file: test_text_procedures.txt\n"}
{"timestamp": "2025-05-31T23:22:27.383438", "type": "ERROR", "message": "Empty or invalid file: test_text_procedures.txt"}
{"timestamp": "2025-05-31T23:22:27.384106", "type": "ERROR", "message": "Error processing file test_text_procedures.txt: Empty or invalid file: test_text_procedures.txt", "traceback": "Traceback (most recent call last):\n  File \"/workspace/llm/WorkApp2/core/document_ingestion/enhanced_file_processor.py\", line 314, in process_file_upload\n    raise ValueError(error_msg)\nValueError: Empty or invalid file: test_text_procedures.txt\n"}
{"timestamp": "2025-05-31T23:22:29.522361", "type": "ERROR", "message": "Empty or invalid file: test_text_procedures.txt"}
{"timestamp": "2025-05-31T23:22:29.523060", "type": "ERROR", "message": "Error processing file test_text_procedures.txt: Empty or invalid file: test_text_procedures.txt", "traceback": "Traceback (most recent call last):\n  File \"/workspace/llm/WorkApp2/core/document_ingestion/enhanced_file_processor.py\", line 314, in process_file_upload\n    raise ValueError(error_msg)\nValueError: Empty or invalid file: test_text_procedures.txt\n"}
{"timestamp": "2025-05-31T23:22:29.524346", "type": "ERROR", "message": "Error in DocumentIngestion during file processing: Error processing file test_text_procedures.txt: Empty or invalid file: test_text_procedures.txt", "traceback": "Traceback (most recent call last):\n  File \"/workspace/llm/WorkApp2/core/document_ingestion/enhanced_file_processor.py\", line 314, in process_file_upload\n    raise ValueError(error_msg)\nValueError: Empty or invalid file: test_text_procedures.txt\n\nThe above exception was the direct cause of the following exception:\n\nTraceback (most recent call last):\n  File \"/workspace/llm/WorkApp2/core/document_ingestion/ingestion_manager.py\", line 84, in process_file\n    chunks = self.file_processor.process_file_upload(file)\n             ^^^^^^^^^^^^^^^^^^^^^^^^^^^^^^^^^^^^^^^^^^^^^\n  File \"/workspace/llm/WorkApp2/utils/error_handling/enhanced_decorators.py\", line 311, in wrapper\n    result = func(*args, **kwargs)\n             ^^^^^^^^^^^^^^^^^^^^^\n  File \"/workspace/llm/WorkApp2/utils/error_handling/enhanced_decorators.py\", line 162, in wrapper\n    raise last_exception\n  File \"/workspace/llm/WorkApp2/utils/error_handling/enhanced_decorators.py\", line 94, in wrapper\n    return func(*args, **kwargs)\n           ^^^^^^^^^^^^^^^^^^^^^\n  File \"/workspace/llm/WorkApp2/core/document_ingestion/enhanced_file_processor.py\", line 338, in process_file_upload\n    raise RuntimeError(error_msg) from e\nRuntimeError: Error processing file test_text_procedures.txt: Empty or invalid file: test_text_procedures.txt\n"}
{"timestamp": "2025-05-31T23:22:30.654864", "type": "ERROR", "message": "Empty or invalid file: test_text_procedures.txt"}
{"timestamp": "2025-05-31T23:22:30.655515", "type": "ERROR", "message": "Error processing file test_text_procedures.txt: Empty or invalid file: test_text_procedures.txt", "traceback": "Traceback (most recent call last):\n  File \"/workspace/llm/WorkApp2/core/document_ingestion/enhanced_file_processor.py\", line 314, in process_file_upload\n    raise ValueError(error_msg)\nValueError: Empty or invalid file: test_text_procedures.txt\n"}
{"timestamp": "2025-05-31T23:22:31.479900", "type": "ERROR", "message": "Empty or invalid file: test_text_procedures.txt"}
{"timestamp": "2025-05-31T23:22:31.480559", "type": "ERROR", "message": "Error processing file test_text_procedures.txt: Empty or invalid file: test_text_procedures.txt", "traceback": "Traceback (most recent call last):\n  File \"/workspace/llm/WorkApp2/core/document_ingestion/enhanced_file_processor.py\", line 314, in process_file_upload\n    raise ValueError(error_msg)\nValueError: Empty or invalid file: test_text_procedures.txt\n"}
{"timestamp": "2025-05-31T23:22:33.806415", "type": "ERROR", "message": "Empty or invalid file: test_text_procedures.txt"}
{"timestamp": "2025-05-31T23:22:33.807167", "type": "ERROR", "message": "Error processing file test_text_procedures.txt: Empty or invalid file: test_text_procedures.txt", "traceback": "Traceback (most recent call last):\n  File \"/workspace/llm/WorkApp2/core/document_ingestion/enhanced_file_processor.py\", line 314, in process_file_upload\n    raise ValueError(error_msg)\nValueError: Empty or invalid file: test_text_procedures.txt\n"}
{"timestamp": "2025-05-31T23:22:33.808499", "type": "ERROR", "message": "Error in DocumentIngestion during file processing: Error processing file test_text_procedures.txt: Empty or invalid file: test_text_procedures.txt", "traceback": "Traceback (most recent call last):\n  File \"/workspace/llm/WorkApp2/core/document_ingestion/enhanced_file_processor.py\", line 314, in process_file_upload\n    raise ValueError(error_msg)\nValueError: Empty or invalid file: test_text_procedures.txt\n\nThe above exception was the direct cause of the following exception:\n\nTraceback (most recent call last):\n  File \"/workspace/llm/WorkApp2/core/document_ingestion/ingestion_manager.py\", line 84, in process_file\n    chunks = self.file_processor.process_file_upload(file)\n             ^^^^^^^^^^^^^^^^^^^^^^^^^^^^^^^^^^^^^^^^^^^^^\n  File \"/workspace/llm/WorkApp2/utils/error_handling/enhanced_decorators.py\", line 311, in wrapper\n    result = func(*args, **kwargs)\n             ^^^^^^^^^^^^^^^^^^^^^\n  File \"/workspace/llm/WorkApp2/utils/error_handling/enhanced_decorators.py\", line 162, in wrapper\n    raise last_exception\n  File \"/workspace/llm/WorkApp2/utils/error_handling/enhanced_decorators.py\", line 94, in wrapper\n    return func(*args, **kwargs)\n           ^^^^^^^^^^^^^^^^^^^^^\n  File \"/workspace/llm/WorkApp2/core/document_ingestion/enhanced_file_processor.py\", line 338, in process_file_upload\n    raise RuntimeError(error_msg) from e\nRuntimeError: Error processing file test_text_procedures.txt: Empty or invalid file: test_text_procedures.txt\n"}
{"timestamp": "2025-05-31T23:22:36.015762", "type": "ERROR", "message": "Empty or invalid file: test_text_procedures.txt"}
{"timestamp": "2025-05-31T23:22:36.016424", "type": "ERROR", "message": "Error processing file test_text_procedures.txt: Empty or invalid file: test_text_procedures.txt", "traceback": "Traceback (most recent call last):\n  File \"/workspace/llm/WorkApp2/core/document_ingestion/enhanced_file_processor.py\", line 314, in process_file_upload\n    raise ValueError(error_msg)\nValueError: Empty or invalid file: test_text_procedures.txt\n"}
{"timestamp": "2025-05-31T23:22:37.120667", "type": "ERROR", "message": "Empty or invalid file: test_text_procedures.txt"}
{"timestamp": "2025-05-31T23:22:37.121318", "type": "ERROR", "message": "Error processing file test_text_procedures.txt: Empty or invalid file: test_text_procedures.txt", "traceback": "Traceback (most recent call last):\n  File \"/workspace/llm/WorkApp2/core/document_ingestion/enhanced_file_processor.py\", line 314, in process_file_upload\n    raise ValueError(error_msg)\nValueError: Empty or invalid file: test_text_procedures.txt\n"}
{"timestamp": "2025-05-31T23:22:39.177642", "type": "ERROR", "message": "Empty or invalid file: test_text_procedures.txt"}
{"timestamp": "2025-05-31T23:22:39.178300", "type": "ERROR", "message": "Error processing file test_text_procedures.txt: Empty or invalid file: test_text_procedures.txt", "traceback": "Traceback (most recent call last):\n  File \"/workspace/llm/WorkApp2/core/document_ingestion/enhanced_file_processor.py\", line 314, in process_file_upload\n    raise ValueError(error_msg)\nValueError: Empty or invalid file: test_text_procedures.txt\n"}
{"timestamp": "2025-05-31T23:22:39.179551", "type": "ERROR", "message": "Error in DocumentIngestion during file processing: Error processing file test_text_procedures.txt: Empty or invalid file: test_text_procedures.txt", "traceback": "Traceback (most recent call last):\n  File \"/workspace/llm/WorkApp2/core/document_ingestion/enhanced_file_processor.py\", line 314, in process_file_upload\n    raise ValueError(error_msg)\nValueError: Empty or invalid file: test_text_procedures.txt\n\nThe above exception was the direct cause of the following exception:\n\nTraceback (most recent call last):\n  File \"/workspace/llm/WorkApp2/core/document_ingestion/ingestion_manager.py\", line 84, in process_file\n    chunks = self.file_processor.process_file_upload(file)\n             ^^^^^^^^^^^^^^^^^^^^^^^^^^^^^^^^^^^^^^^^^^^^^\n  File \"/workspace/llm/WorkApp2/utils/error_handling/enhanced_decorators.py\", line 311, in wrapper\n    result = func(*args, **kwargs)\n             ^^^^^^^^^^^^^^^^^^^^^\n  File \"/workspace/llm/WorkApp2/utils/error_handling/enhanced_decorators.py\", line 162, in wrapper\n    raise last_exception\n  File \"/workspace/llm/WorkApp2/utils/error_handling/enhanced_decorators.py\", line 94, in wrapper\n    return func(*args, **kwargs)\n           ^^^^^^^^^^^^^^^^^^^^^\n  File \"/workspace/llm/WorkApp2/core/document_ingestion/enhanced_file_processor.py\", line 338, in process_file_upload\n    raise RuntimeError(error_msg) from e\nRuntimeError: Error processing file test_text_procedures.txt: Empty or invalid file: test_text_procedures.txt\n"}
